Workbook

Sheet README
A1: Valuation Workpaper — Cover & User Guide
A2: Auto-generated by the Orionmano valuation pipeline. Read this sheet first. Every figure on every downstream tab is driven by a named range on the Inputs sheet.
B4: Engagement metadata
B5: Company | C5: =company_name -> Sample TechCo Holdings Limited
B6: Country of incorporation | C6: =company_country -> SG
B7: Industry (US) | C7: =company_industry_us -> Software (Internet)
B8: Industry (Global) | C8: =company_industry_global -> Software (Internet)
B9: Report purpose | C9: =report_purpose -> IPO pricing
B10: Accounting standard | C10: =accounting_standard -> IFRS
B11: Client (engaging party) | C11: =client_name -> Sample TechCo Holdings Limited
B12: Engagement partner | C12: =engagement_team_partner -> A. Lee
B13: Engagement manager | C13: =engagement_team_manager -> T. Wong
B14: Department | C14: =engagement_department -> Valuation Advisory
B17: Currency & units
B18: Reporting currency | C18: =currency -> USD
B19: Unit | C19: =unit -> '000
B20: Secondary currency | C20: =currency_alt -> 0
B21: FX rate to alt | C21: =fx_rate_alt -> 0
B22: Note | C22: All monetary values throughout this workbook are denominated in [currency] [unit] unless explicitly stated otherwise.
B24: Valuation methodologies & weights
B25: Methodology | C25: Weight | D25: Sheet | E25: Notes
B26: Discounted Cash Flow (DCF) | C26: =weight_dcf -> 0.5 | D26: DCF / DCF (Independent) | E26: Two-scenario WACC; Gordon-growth or exit-multiple terminal.
B27: Comparable Companies (CoCo) | C27: =weight_comps -> 0.3 | D27: Comps / CoCo Multiples | E27: Q1/Median/Q3 NTM trading multiples × target metrics.
B28: Precedent Transactions | C28: =weight_precedent -> 0.2 | D28: Precedent | E28: Mean EV/EBITDA × Y1 EBITDA from observed M&A deals.
B29: Net Asset Value (NAV) | C29: =weight_nav -> 0 | D29: — | E29: Asset-based; typically 0% for going-concern targets.
B30: Total weight | C30: =weight_dcf+weight_comps+weight_precedent+weight_nav -> 1 | D30: Must equal 100%
B33: Sheet index
B34: # | C34: Sheet | D34: Purpose
B35: 1 | C35: README | D35: Instructions, version, manual-input checklist
B36: 2 | C36: Dashboard | D36: High-level outputs: EV, Net debt, Surplus, Equity, WACC, terminal g + benchmark charts
B37: 3 | C37: Inputs | D37: Single source of truth — all driver parameters
B38: 4 | C38: Historical FS | D38: 3-5 yr audited income statement + balance sheet (PBC raw)
B39: 5 | C39: Projections | D39: Year-by-year forecast lines driven by Inputs
B40: 6 | C40: DCF | D40: FCFF schedule, partial-year discount, PV, terminal value
B41: 7 | C41: DCF (Independent) | D41: Parallel scenario with independent WACC range
B42: 8 | C42: Comps | D42: Apply CoCo multiples to target metrics; implied EV/Sales, EV/EBITDA, P/E
B43: 9 | C43: Football Field | D43: Valuation range chart per methodology + weighted selected range
B44: 10 | C44: WACC | D44: Full Ke + Kd build with Per-Mgmt and Independent scenarios
B45: 11 | C45: CoCo Selection | D45: Comparable company selection with tier flags + market cap
... B54: 20 | C54: Valuation Summary | D54: Final EV -> Equity -> Per share with all weighting and adjustments
...

Sheet Dashboard
A1: Valuation Dashboard
A2: =company_name & " · " & report_purpose -> Sample TechCo Holdings Limited · IPO pricing
B4: Headline values (Per-Management scenario)
C5: Enterprise Value | D5: Equity (after DLOM/DLOC) | E5: Per share (basic) | F5: WACC | G5: Terminal growth
C6: ='Valuation Summary'!C7 -> 327299.06 | D6: ='Valuation Summary'!C10 -> 239563.36 | E6: ='Valuation Summary'!C16 -> 0.95825345 | F6: =wacc_per_mgmt -> 0.13905529 | G6: =terminal_growth_rate -> 0.03
B8: Independent scenario | C8: ='Valuation Summary'!D7 -> 273676.53 | D8: ='Valuation Summary'!D10 -> 203100.04 | E8: ='Valuation Summary'!D16 -> 0.81240016 | F8: =wacc_indep -> 0.1558895 | G8: =terminal_growth_rate -> 0.03
B11: Methodology range — enterprise value
B12: Methodology | C12: Low | D12: Mid | E12: High | F12: Weight | G12: Weighted mid | H12: Notes
B13: DCF (across scenarios) | C13: ='Football Field'!B7 -> 273676.53 | D13: ='Football Field'!C7 -> 300487.8 | E13: ='Football Field'!D7 -> 327299.06 | F13: =weight_dcf -> 0.5 | G13: ='Football Field'!F7 -> 150243.9 | H13: Per-Mgmt vs Independent WACC.
B14: Comparable Companies | C14: ='Football Field'!B11 -> 50820.5 | D14: ='Football Field'!C11 -> 227069.33 | E14: ='Football Field'!D11 -> 485750 | F14: =weight_comps -> 0.3 | G14: ='Football Field'!F11 -> 68120.8 | H14: Cross-check vs DCF (±10% band).
B15: Precedent Transactions | C15: ='Football Field'!B12 -> 0 | D15: ='Football Field'!C12 -> 243600 | E15: ='Football Field'!D12 -> 0 | F15: =weight_precedent -> 0.2 | G15: ='Football Field'!F12 -> 48720 | H15: Cross-check vs DCF (±10% band).
B17: Concluded EV (DCF primary) | G17: ='Football Field'!F16 -> 267084.7
B18: Selected band (low / mid / high) | C18: =selected_low -> 0 | D18: =selected_mid -> 0 | E18: =selected_high -> 0
B20: CoCo trading multiples — benchmark stats
B21: Multiple | C21: Min | D21: Q1 | E21: Median | F21: Q3 | G21: Max | H21: Mean
B22: EV / Sales NTM | C22: ='CoCo Multiples'!F42 -> 2.7 | D22: ='CoCo Multiples'!F41 -> 3.075 | E22: ='CoCo Multiples'!F39 -> 3.35 | F22: ='CoCo Multiples'!F38 -> 3.775 | G22: ='CoCo Multiples'!F37 -> 4.6 | H22: ='CoCo Multiples'!F40 -> 3.5
B23: EV / EBITDA NTM | C23: ='CoCo Multiples'!H42 -> 12 | D23: ='CoCo Multiples'!H41 -> 13.125 | E23: ='CoCo Multiples'!H39 -> 14.25 | F23: ='CoCo Multiples'!H38 -> 15.75 | G23: ='CoCo Multiples'!H37 -> 18 | H23: ='CoCo Multiples'!H40 -> 14.625
B24: P / E NTM | C24: ='CoCo Multiples'!J42 -> 18 | D24: ='CoCo Multiples'!J41 -> 19.5 | E24: ='CoCo Multiples'!J39 -> 21 | F24: ='CoCo Multiples'!J38 -> 23 | G24: ='CoCo Multiples'!J37 -> 26 | H24: ='CoCo Multiples'!J40 -> 21.5
B25: EV / Sales LTM | C25: ='CoCo Multiples'!E42 -> 3.1 | D25: ='CoCo Multiples'!E41 -> 3.625 | E25: ='CoCo Multiples'!E39 -> 4 | F25: ='CoCo Multiples'!E38 -> 4.525 | G25: ='CoCo Multiples'!E37 -> 5.5 | H25: ='CoCo Multiples'!E40 -> 4.15
B26: EV / EBITDA LTM | C26: ='CoCo Multiples'!G42 -> 14 | D26: ='CoCo Multiples'!G41 -> 15.875 | E26: ='CoCo Multiples'!G39 -> 17.25 | F26: ='CoCo Multiples'!G38 -> 19 | G26: ='CoCo Multiples'!G37 -> 22 | H26: ='CoCo Multiples'!G40 -> 17.625
B27: P / E LTM | C27: ='CoCo Multiples'!I42 -> 21 | D27: ='CoCo Multiples'!I41 -> 23.25 | E27: ='CoCo Multiples'!I39 -> 25 | F27: ='CoCo Multiples'!I38 -> 27.5 | G27: ='CoCo Multiples'!I37 -> 32 | H27: ='CoCo Multiples'!I40 -> 25.75
B30: Sensitivity — EV (WACC × terminal growth, Per-Mgmt)
B31: Full grid is on the Sensitivity tab. This panel shows EV at the base case (centre cell) plus ±1 step in each direction.
B32: WACC ↓ / g → | C32: g − 1 step | D32: Base g | E32: g + 1 step
B33: WACC − 1 step | C33: =INDEX(Sensitivity!C7:M17,sens_wacc_count,sens_terminal_g_count) -> 321729.72 | D33: =INDEX(Sensitivity!C7:M17,sens_wacc_count,sens_terminal_g_count+1) -> 334962.23 | E33: =INDEX(Sensitivity!C7:M17,sens_wacc_count,sens_terminal_g_count+2) -> 349530.61
B34: Base WACC | C34: =INDEX(Sensitivity!C7:M17,sens_wacc_count+1,sens_terminal_g_count) -> 304415.7 | D34: =INDEX(Sensitivity!C7:M17,sens_wacc_count+1,sens_terminal_g_count+1) -> 316279.27 | E34: =INDEX(Sensitivity!C7:M17,sens_wacc_count+1,sens_terminal_g_count+2) -> 329282.96
B35: WACC + 1 step | C35: =INDEX(Sensitivity!C7:M17,sens_wacc_count+2,sens_terminal_g_count) -> 288605.39 | D35: =INDEX(Sensitivity!C7:M17,sens_wacc_count+2,sens_terminal_g_count+1) -> 299285.38 | E35: =INDEX(Sensitivity!C7:M17,sens_wacc_count+2,sens_terminal_g_count+2) -> 310944.68
B38: Backtesting — historical revenue vs Y0 base
B39: Sanity check: Y0 base revenue (cascading into Projections) should equal the most-recent FY-1 audited revenue.
C40: FY-3 | D40: FY-2 | E40: FY-1 | F40: Y0 (Projections) | G40: Δ Y0 vs FY-1
B41: Revenue | C41: ='Historical FS'!E7 -> 86000 | D41: ='Historical FS'!F7 -> 95000 | E41: ='Historical FS'!G7 -> 100000 | F41: =revenue_y0 -> 100000 | G41: =IFERROR(revenue_y0/'Historical FS'!G7-1,"n/a") -> 0
B42: EBITDA | C42: ='Historical FS'!E13 -> 8600 | D42: ='Historical FS'!F13 -> 9500 | E42: ='Historical FS'!G13 -> 10000 | F42: — | G42: —
B45: Open the web dashboard (Orionmano · Companies · this entity · Valuation tab) for interactive Football Field, Sensitivity heatmap, FCFF projection, and CoCo multiple charts.

Sheet Inputs
A1: Inputs — single source of truth for all valuation parameters
A2: Every parameter below is a named range. Downstream sheets reference these by name, not by cell coordinate. The Source / Source detail / Notes columns record the audit trail.
A4: id | B4: Parameter | C4: Type | D4: Value (Per Mgmt) | E4: Value (Independent) | F4: Source | G4: Source detail | H4: Notes
A6: Section A — Engagement metadata (Core)
A7: company_name | B7: Company name | C7: text | D7: Sample TechCo Holdings Limited | F7: Engagement Letter | G7: EL dated 2026-03-15
A8: company_country | B8: Country of incorporation | C8: enum | D8: SG
A9: company_industry_us | B9: Industry (US classification) | C9: enum | D9: Software (Internet)
A10: company_industry_global | B10: Industry (Global classification) | C10: enum | D10: Software (Internet)
A11: report_purpose | B11: Report purpose | C11: enum | D11: IPO pricing
A12: accounting_standard | B12: Accounting standard | C12: enum | D12: IFRS
A13: engagement_team_partner | B13: Engagement partner | C13: text | D13: A. Lee
A14: engagement_team_manager | B14: Engagement manager | C14: text | D14: T. Wong
A15: engagement_department | B15: Department | C15: text | D15: Valuation Advisory
A16: client_name | B16: Client (engaging party) | C16: text | D16: Sample TechCo Holdings Limited
A18: Section B — Currency & units (Core)
A19: currency | B19: Reporting currency | C19: enum | D19: USD
A20: unit | B20: Unit of presentation | C20: enum | D20: '000
A21: currency_alt | B21: Secondary display currency (optional) | C21: enum
A22: fx_rate_alt | B22: FX rate to alternate currency | C22: number
A24: Section C — Tax rule (Core)
A25: tax_jurisdiction | B25: Tax jurisdiction | C25: enum | D25: SG
A26: tax_type | B26: Tax structure | C26: enum | D26: flat | H26: flat | two_tier | progressive
A27: tax_rate_low | B27: Low-tier rate | C27: percentage | D27: 0.17
A28: tax_rate_high | B28: High-tier rate (or flat rate) | C28: percentage | D28: 0.17 | F28: Manual | G28: Singapore corporate tax rate 17% flat
A29: tax_threshold | B29: Threshold between tiers | C29: currency
A30: tax_effective_rate | B30: Effective rate (override) | C30: percentage
A32: Section D — Projection drivers (Core)
A33: projection_years | B33: Explicit forecast years | C33: number | D33: 5
A34: revenue_growth_method | B34: Revenue growth method | C34: enum | D34: per_year | H34: flat | declining | staged | per_year
A35: revenue_y0 | B35: Revenue base (Y0 / LTM) | C35: currency | D35: 100000 | F35: Audited FS | G35: FY2025 Audited FS, Consolidated P&L, p.34 | H35: Last full reported year
A36: nwc_y0 | B36: Net working capital (Y0) | C36: currency | D36: 8000 | F36: Audited FS | G36: FY2025 Audited FS, Balance Sheet, p.36 (current assets ex-cash − current liabilities ex-debt)
A37: gross_profit_y0 | B37: Gross profit (Y0) | C37: currency | H37: Audited Y0 gross profit; populates the Projections Y0 gross-profit cell
A38: opex_y0 | B38: Operating expenses (Y0) | C38: currency | H38: Audited Y0 opex (negative); populates the Projections Y0 opex cell
A39: ebitda_y0 | B39: EBITDA (Y0) | C39: currency | H39: Audited Y0 EBITDA; populates the Projections Y0 EBITDA cell
A40: ebit_y0 | B40: EBIT (Y0) | C40: currency | H40: Audited Y0 EBIT; populates the Projections Y0 EBIT cell
A41: tax_y0 | B41: Tax (Y0) | C41: currency | H41: Audited Y0 tax expense (negative); populates the Projections Y0 tax cell
A42: net_income_y0 | B42: Net income (Y0) | C42: currency | H42: Audited Y0 net income; populates the Projections Y0 net-income cell
A43: revenue_growth_y1 | B43: Revenue growth (total) (Y1) | C43: percentage | D43: 0.45
A44: revenue_growth_y2 | B44: Revenue growth (total) (Y2) | C44: percentage | D44: 0.3
A45: revenue_growth_y3 | B45: Revenue growth (total) (Y3) | C45: percentage | D45: 0.22
...

Sheet Historical FS
A1: Historical Financial Statements
A2: 3-5 years audited income statement + balance sheet. Manual entry from client PBC. Y0 base values for the Projections sheet (revenue, NWC) should be populated from this sheet.
A4: Line item | B4: Unit | C4: FY-5 | D4: FY-4 | E4: FY-3 | F4: FY-2 | G4: FY-1
A6: Income Statement
A7: Revenue | B7: (currency × unit) | C7: 70000 | D7: 78000 | E7: 86000 | F7: 95000 | G7: 100000
A8: Cost of revenue | B8: (currency × unit) | C8: -42000 | D8: -46800 | E8: -51600 | F8: -57000 | G8: -60000
A9: Gross profit | B9: (currency × unit) | C9: 28000 | D9: 31200 | E9: 34400 | F9: 38000 | G9: 40000
A10: Operating expenses | B10: (currency × unit) | C10: -21000 | D10: -23400 | E10: -25800 | F10: -28500 | G10: -30000
A11: Selling, general & admin | B11: (currency × unit) | C11: -15000 | D11: -16800 | E11: -18500 | F11: -20400 | G11: -21500
A12: Research & development | B12: (currency × unit) | C12: -6000 | D12: -6600 | E12: -7300 | F12: -8100 | G12: -8500
A13: EBITDA | B13: (currency × unit) | C13: 7000 | D13: 7800 | E13: 8600 | F13: 9500 | G13: 10000
A14: Depreciation & amortization | B14: (currency × unit) | C14: -2100 | D14: -2340 | E14: -2580 | F14: -2850 | G14: -3000
A15: EBIT (Operating income) | B15: (currency × unit) | C15: 4900 | D15: 5460 | E15: 6020 | F15: 6650 | G15: 7000
A16: Interest expense | B16: (currency × unit) | C16: -800 | D16: -800 | E16: -750 | F16: -700 | G16: -700
A17: Other income / (expense) | B17: (currency × unit) | C17: 0 | D17: 0 | E17: 0 | F17: 0 | G17: 0
A18: Profit before tax | B18: (currency × unit) | C18: 4100 | D18: 4660 | E18: 5270 | F18: 5950 | G18: 6300
... A20: Net income | B20: (currency × unit) | C20: 3116 | D20: 3542 | E20: 4005 | F20: 4522 | G20: 4788
A22: Balance Sheet
A23: Current assets | B23: (currency × unit)
A24: Cash and equivalents | B24: (currency × unit) | C24: 3000 | D24: 3500 | E24: 4500 | F24: 5500 | G24: 6500
A25: Accounts receivable | B25: (currency × unit) | C25: 10000 | D25: 11000 | E25: 12000 | F25: 13000 | G25: 14000
A26: Inventory | B26: (currency × unit) | C26: 4500 | D26: 5000 | E26: 5500 | F26: 6000 | G26: 6500
A27: Prepaid expenses | B27: (currency × unit) | C27: 800 | D27: 900 | E27: 1000 | F27: 1100 | G27: 1200
A28: Total current assets | B28: (currency × unit) | C28: 18300 | D28: 20400 | E28: 23000 | F28: 25600 | G28: 28200
A29: Non-current assets | B29: (currency × unit)
A30: Property, plant & equipment | B30: (currency × unit) | C30: 22000 | D30: 26000 | E30: 30000 | F30: 34000 | G30: 38000
A31: Intangible assets | B31: (currency × unit) | C31: 3500 | D31: 3500 | E31: 3500 | F31: 3500 | G31: 3500
A32: Other long-term assets | B32: (currency × unit) | C32: 1500 | D32: 1500 | E32: 1500 | F32: 1500 | G32: 1500
A33: Total assets | B33: (currency × unit) | C33: 45300 | D33: 51400 | E33: 58000 | F33: 64600 | G33: 71200
A35: Current liabilities | B35: (currency × unit)
A36: Accounts payable | B36: (currency × unit) | C36: -7000 | D36: -7700 | E36: -8500 | F36: -9300 | G36: -10000
A37: Short-term debt | B37: (currency × unit) | C37: -3000 | D37: -2500 | E37: -2000 | F37: -2000 | G37: -2000
A38: Other current liabilities | B38: (currency × unit) | C38: -2000 | D38: -2200 | E38: -2400 | F38: -2700 | G38: -3000
A39: Total current liabilities | B39: (currency × unit) | C39: -12000 | D39: -12400 | E39: -12900 | F39: -14000 | G39: -15000
A40: Non-current liabilities | B40: (currency × unit)
A41: Long-term debt | B41: (currency × unit) | C41: -12000 | D41: -11000 | E41: -9500 | F41: -9000 | G41: -8500
A42: Other long-term liabilities | B42: (currency × unit) | C42: -1000 | D42: -1000 | E42: -1000 | F42: -1000 | G42: -1000
A43: Total liabilities | B43: (currency × unit) | C43: -25000 | D43: -24400 | E43: -23400 | F43: -24000 | G43: -24500
A44: Total equity | B44: (currency × unit) | C44: 20300 | D44: 27000 | E44: 34600 | F44: 40600 | G44: 46700
A46: Derived metrics (calculated)
...

Sheet Projections
A1: Projections — driven by Inputs
A2: Year-by-year forecast lines. Every assumption flows from Inputs named ranges. Edit a value on Inputs and this sheet recalculates.
A4: Line item | B4: Unit | C4: Y0 (base) | D4: Y1 | E4: Y2 | F4: Y3 | G4: Y4 | H4: Y5
A6: Revenue & growth
A8: Revenue - Primary | B8: (from Inputs) | C8: =revenue_y0 -> 100000 | D8: =C8*(1+IF(ISNUMBER(revenue_growth_primary_y1),revenue_growth_primary_y1,revenue_growth_y1)) -> 145000 | E8: =D8*(1+IF(ISNUMBER(revenue_growth_primary_y2),revenue_growth_primary_y2,revenue_growth_y2)) -> 188500 | F8: =E8*(1+IF(ISNUMBER(revenue_growth_primary_y3),revenue_growth_primary_y3,revenue_growth_y3)) -> 229970 | G8: =F8*(1+IF(ISNUMBER(revenue_growth_primary_y4),revenue_growth_primary_y4,revenue_growth_y4)) -> 266765.2 | H8: =G8*(1+IF(ISNUMBER(revenue_growth_primary_y5),revenue_growth_primary_y5,revenue_growth_y5)) -> 293441.72
A9: Core business baseline carryover | D9: =C8 -> 100000 | E9: =D8 -> 145000 | F9: =E8 -> 188500 | G9: =F8 -> 229970 | H9: =G8 -> 266765.2
A10: Capped baseline growth | D10: =C8*D11 -> 45000 | E10: =D8*E11 -> 43500 | F10: =E8*F11 -> 41470 | G10: =F8*G11 -> 36795.2 | H10: =G8*H11 -> 26676.52
A11: Revenue growth (primary) | B11: % | D11: =IF(ISNUMBER(revenue_growth_primary_y1),revenue_growth_primary_y1,revenue_growth_y1) -> 0.45 | E11: =IF(ISNUMBER(revenue_growth_primary_y2),revenue_growth_primary_y2,revenue_growth_y2) -> 0.3 | F11: =IF(ISNUMBER(revenue_growth_primary_y3),revenue_growth_primary_y3,revenue_growth_y3) -> 0.22 | G11: =IF(ISNUMBER(revenue_growth_primary_y4),revenue_growth_primary_y4,revenue_growth_y4) -> 0.16 | H11: =IF(ISNUMBER(revenue_growth_primary_y5),revenue_growth_primary_y5,revenue_growth_y5) -> 0.1
A12: Revenue - Others | B12: (currency × unit) | C12: 0 | D12: =D25-D8 -> 0 | E12: =E25-E8 -> 0 | F12: =F25-F8 -> 0 | G12: =G25-G8 -> 0 | H12: =H25-H8 -> 0
A13: Core business excess upside | D13: =IF(AND(NOT(INDEX(segments_table,1,1)=""),EXACT(INDEX(segments_table,1,19),"core")),D75,0)+IF(AND(NOT(INDEX(segments_table,2,1)=""),EXACT(INDEX(segments_table,2,19),"core")),D79,0)+IF(AND(NOT(INDEX(segments_table,3,1)=""),EXACT(INDEX(segments_table,3,19),"core")),D83,0)+IF(AND(NOT(INDEX(segments_table,4,1)=""),EXACT(INDEX(segments_table,4,19),"core")),D87,0)+IF(AND(NOT(INDEX(segments_table,5,1)=""),EXACT(INDEX(segments_table,5,19),"core")),D91,0)+IF(AND(NOT(INDEX(segments_table,6,1)=""),EXACT(INDEX(segments_table,6,19),"core")),D95,0)+IF(AND(NOT(INDEX(segments_table,7,1)=""),EXACT(INDEX(segments_table,7,19),"core")),D99,0)+IF(AND(NOT(INDEX(segments_table,8,1)=""),EXACT(INDEX(segments_table,8,19),"core")),D103,0)-D8 -> -145000 | E13: =IF(AND(NOT(INDEX(segments_table,1,1)=""),EXACT(INDEX(segments_table,1,19),"core")),E75,0)+IF(AND(NOT(INDEX(segments_table,2,1)=""),EXACT(INDEX(segments_table,2,19),"core")),E79,0)+IF(AND(NOT(INDEX(segments_table,3,1)=""),EXACT(INDEX(segments_table,3,19),"core")),E83,0)+IF(AND(NOT(INDEX(segments_table,4,1)=""),EXACT(INDEX(segments_table,4,19),"core")),E87,0)+IF(AND(NOT(INDEX(segments_table,5,1)=""),EXACT(INDEX(segments_table,5,19),"core")),E91,0)+IF(AND(NOT(INDEX(segments_table,6,1)=""),EXACT(INDEX(segments_table,6,19),"core")),E95,0)+IF(AND(NOT(INDEX(segments_table,7,1)=""),EXACT(INDEX(segments_table,7,19),"core")),E99,0)+IF(AND(NOT(INDEX(segments_table,8,1)=""),EXACT(INDEX(segments_table,8,19),"core")),E103,0)-E8 -> -188500 | F13: =IF(AND(NOT(INDEX(segments_table,1,1)=""),EXACT(INDEX(segments_table,1,19),"core")),F75,0)+IF(AND(NOT(INDEX(segments_table,2,1)=""),EXACT(INDEX(segments_table,2,19),"core")),F79,0)+IF(AND(NOT(INDEX(segments_table,3,1)=""),EXACT(INDEX(segments_table,3,19),"core")),F83,0)+IF(AND(NOT(INDEX(segments_table,4,1)=""),EXACT(INDEX(segments_table,4,19),"core")),F87,0)+IF(AND(NOT(INDEX(segments_table,5,1)=""),EXACT(INDEX(segments_table,5,19),"core")),F91,0)+IF(AND(NOT(INDEX(segments_table,6,1)=""),EXACT(INDEX(segments_table,6,19),"core")),F95,0)+IF(AND(NOT(INDEX(segments_table,7,1)=""),EXACT(INDEX(segments_table,7,19),"core")),F99,0)+IF(AND(NOT(INDEX(segments_table,8,1)=""),EXACT(INDEX(segments_table,8,19),"core")),F103,0)-F8 -> -229970 | G13: =IF(AND(NOT(INDEX(segments_table,1,1)=""),EXACT(INDEX(segments_table,1,19),"core")),G75,0)+IF(AND(NOT(INDEX(segments_table,2,1)=""),EXACT(INDEX(segments_table,2,19),"core")),G79,0)+IF(AND(NOT(INDEX(segments_table,3,1)=""),EXACT(INDEX(segments_table,3,19),"core")),G83,0)+IF(AND(NOT(INDEX(segments_table,4,1)=""),EXACT(INDEX(segments_table,4,19),"core")),G87,0)+IF(AND(NOT(INDEX(segments_table,5,1)=""),EXACT(INDEX(segments_table,5,19),"core")),G91,0)+IF(AND(NOT(INDEX(segments_table,6,1)=""),EXACT(INDEX(segments_table,6,19),"core")),G95,0)+IF(AND(NOT(INDEX(segments_table,7,1)=""),EXACT(INDEX(segments_table,7,19),"core")),G99,0)+IF(AND(NOT(INDEX(segments_table,8,1)=""),EXACT(INDEX(segments_table,8,19),"core")),G103,0)-G8 -> -266765.2 | H13: =IF(AND(NOT(INDEX(segments_table,1,1)=""),EXACT(INDEX(segments_table,1,19),"core")),H75,0)+IF(AND(NOT(INDEX(segments_table,2,1)=""),EXACT(INDEX(segments_table,2,19),"core")),H79,0)+IF(AND(NOT(INDEX(segments_table,3,1)=""),EXACT(INDEX(segments_table,3,19),"core")),H83,0)+IF(AND(NOT(INDEX(segments_table,4,1)=""),EXACT(INDEX(segments_table,4,19),"core")),H87,0)+IF(AND(NOT(INDEX(segments_table,5,1)=""),EXACT(INDEX(segments_table,5,19),"core")),H91,0)+IF(AND(NOT(INDEX(segments_table,6,1)=""),EXACT(INDEX(segments_table,6,19),"core")),H95,0)+IF(AND(NOT(INDEX(segments_table,7,1)=""),EXACT(INDEX(segments_table,7,19),"core")),H99,0)+IF(AND(NOT(INDEX(segments_table,8,1)=""),EXACT(INDEX(segments_table,8,19),"core")),H103,0)-H8 -> -293441.72
A14: =IF(OR(INDEX(segments_table,1,1)="",EXACT(INDEX(segments_table,1,19),"core")),""," "&INDEX(segments_table,1,1)) | D14: =IF(OR(INDEX(segments_table,1,1)="",EXACT(INDEX(segments_table,1,19),"core")),0,D75) -> 0 | E14: =IF(OR(INDEX(segments_table,1,1)="",EXACT(INDEX(segments_table,1,19),"core")),0,E75) -> 0 | F14: =IF(OR(INDEX(segments_table,1,1)="",EXACT(INDEX(segments_table,1,19),"core")),0,F75) -> 0 | G14: =IF(OR(INDEX(segments_table,1,1)="",EXACT(INDEX(segments_table,1,19),"core")),0,G75) -> 0 | H14: =IF(OR(INDEX(segments_table,1,1)="",EXACT(INDEX(segments_table,1,19),"core")),0,H75) -> 0
A15: =IF(OR(INDEX(segments_table,2,1)="",EXACT(INDEX(segments_table,2,19),"core")),""," "&INDEX(segments_table,2,1)) | D15: =IF(OR(INDEX(segments_table,2,1)="",EXACT(INDEX(segments_table,2,19),"core")),0,D79) -> 0 | E15: =IF(OR(INDEX(segments_table,2,1)="",EXACT(INDEX(segments_table,2,19),"core")),0,E79) -> 0 | F15: =IF(OR(INDEX(segments_table,2,1)="",EXACT(INDEX(segments_table,2,19),"core")),0,F79) -> 0 | G15: =IF(OR(INDEX(segments_table,2,1)="",EXACT(INDEX(segments_table,2,19),"core")),0,G79) -> 0 | H15: =IF(OR(INDEX(segments_table,2,1)="",EXACT(INDEX(segments_table,2,19),"core")),0,H79) -> 0
A16: =IF(OR(INDEX(segments_table,3,1)="",EXACT(INDEX(segments_table,3,19),"core")),""," "&INDEX(segments_table,3,1)) | D16: =IF(OR(INDEX(segments_table,3,1)="",EXACT(INDEX(segments_table,3,19),"core")),0,D83) -> 0 | E16: =IF(OR(INDEX(segments_table,3,1)="",EXACT(INDEX(segments_table,3,19),"core")),0,E83) -> 0 | F16: =IF(OR(INDEX(segments_table,3,1)="",EXACT(INDEX(segments_table,3,19),"core")),0,F83) -> 0 | G16: =IF(OR(INDEX(segments_table,3,1)="",EXACT(INDEX(segments_table,3,19),"core")),0,G83) -> 0 | H16: =IF(OR(INDEX(segments_table,3,1)="",EXACT(INDEX(segments_table,3,19),"core")),0,H83) -> 0
A17: =IF(OR(INDEX(segments_table,4,1)="",EXACT(INDEX(segments_table,4,19),"core")),""," "&INDEX(segments_table,4,1)) | D17: =IF(OR(INDEX(segments_table,4,1)="",EXACT(INDEX(segments_table,4,19),"core")),0,D87) -> 0 | E17: =IF(OR(INDEX(segments_table,4,1)="",EXACT(INDEX(segments_table,4,19),"core")),0,E87) -> 0 | F17: =IF(OR(INDEX(segments_table,4,1)="",EXACT(INDEX(segments_table,4,19),"core")),0,F87) -> 0 | G17: =IF(OR(INDEX(segments_table,4,1)="",EXACT(INDEX(segments_table,4,19),"core")),0,G87) -> 0 | H17: =IF(OR(INDEX(segments_table,4,1)="",EXACT(INDEX(segments_table,4,19),"core")),0,H87) -> 0
A18: =IF(OR(INDEX(segments_table,5,1)="",EXACT(INDEX(segments_table,5,19),"core")),""," "&INDEX(segments_table,5,1)) | D18: =IF(OR(INDEX(segments_table,5,1)="",EXACT(INDEX(segments_table,5,19),"core")),0,D91) -> 0 | E18: =IF(OR(INDEX(segments_table,5,1)="",EXACT(INDEX(segments_table,5,19),"core")),0,E91) -> 0 | F18: =IF(OR(INDEX(segments_table,5,1)="",EXACT(INDEX(segments_table,5,19),"core")),0,F91) -> 0 | G18: =IF(OR(INDEX(segments_table,5,1)="",EXACT(INDEX(segments_table,5,19),"core")),0,G91) -> 0 | H18: =IF(OR(INDEX(segments_table,5,1)="",EXACT(INDEX(segments_table,5,19),"core")),0,H91) -> 0
A19: =IF(OR(INDEX(segments_table,6,1)="",EXACT(INDEX(segments_table,6,19),"core")),""," "&INDEX(segments_table,6,1)) | D19: =IF(OR(INDEX(segments_table,6,1)="",EXACT(INDEX(segments_table,6,19),"core")),0,D95) -> 0 | E19: =IF(OR(INDEX(segments_table,6,1)="",EXACT(INDEX(segments_table,6,19),"core")),0,E95) -> 0 | F19: =IF(OR(INDEX(segments_table,6,1)="",EXACT(INDEX(segments_table,6,19),"core")),0,F95) -> 0 | G19: =IF(OR(INDEX(segments_table,6,1)="",EXACT(INDEX(segments_table,6,19),"core")),0,G95) -> 0 | H19: =IF(OR(INDEX(segments_table,6,1)="",EXACT(INDEX(segments_table,6,19),"core")),0,H95) -> 0
A20: =IF(OR(INDEX(segments_table,7,1)="",EXACT(INDEX(segments_table,7,19),"core")),""," "&INDEX(segments_table,7,1)) | D20: =IF(OR(INDEX(segments_table,7,1)="",EXACT(INDEX(segments_table,7,19),"core")),0,D99) -> 0 | E20: =IF(OR(INDEX(segments_table,7,1)="",EXACT(INDEX(segments_table,7,19),"core")),0,E99) -> 0 | F20: =IF(OR(INDEX(segments_table,7,1)="",EXACT(INDEX(segments_table,7,19),"core")),0,F99) -> 0 | G20: =IF(OR(INDEX(segments_table,7,1)="",EXACT(INDEX(segments_table,7,19),"core")),0,G99) -> 0 | H20: =IF(OR(INDEX(segments_table,7,1)="",EXACT(INDEX(segments_table,7,19),"core")),0,H99) -> 0
A21: =IF(OR(INDEX(segments_table,8,1)="",EXACT(INDEX(segments_table,8,19),"core")),""," "&INDEX(segments_table,8,1)) | D21: =IF(OR(INDEX(segments_table,8,1)="",EXACT(INDEX(segments_table,8,19),"core")),0,D103) -> 0 | E21: =IF(OR(INDEX(segments_table,8,1)="",EXACT(INDEX(segments_table,8,19),"core")),0,E103) -> 0 | F21: =IF(OR(INDEX(segments_table,8,1)="",EXACT(INDEX(segments_table,8,19),"core")),0,F103) -> 0 | G21: =IF(OR(INDEX(segments_table,8,1)="",EXACT(INDEX(segments_table,8,19),"core")),0,G103) -> 0 | H21: =IF(OR(INDEX(segments_table,8,1)="",EXACT(INDEX(segments_table,8,19),"core")),0,H103) -> 0
A22: Unallocated model adjustment | D22: =D12-D13-SUM(D14:D21) -> 145000 | E22: =E12-E13-SUM(E14:E21) -> 188500 | F22: =F12-F13-SUM(F14:F21) -> 229970 | G22: =G12-G13-SUM(G14:G21) -> 266765.2 | H22: =H12-H13-SUM(H14:H21) -> 293441.72
A23: Sum of Revenue - Others (tie-out) | D23: =SUM(D13:D22) -> 0 | E23: =SUM(E13:E22) -> 0 | F23: =SUM(F13:F22) -> 0 | G23: =SUM(G13:G22) -> 0 | H23: =SUM(H13:H22) -> 0
A24: Other revenue growth | B24: % | D24: =IFERROR(D12/C12-1,"") | E24: =IFERROR(E12/D12-1,"") | F24: =IFERROR(F12/E12-1,"") | G24: =IFERROR(G12/F12-1,"") | H24: =IFERROR(H12/G12-1,"")
A25: Total Revenue | B25: (from Inputs) | C25: =revenue_y0 -> 100000 | D25: =C25*(1+revenue_growth_y1) -> 145000 | E25: =D25*(1+revenue_growth_y2) -> 188500 | F25: =E25*(1+revenue_growth_y3) -> 229970 | G25: =F25*(1+revenue_growth_y4) -> 266765.2 | H25: =G25*(1+revenue_growth_y5) -> 293441.72
A26: Revenue growth (total) | B26: % | D26: =revenue_growth_y1 -> 0.45 | E26: =revenue_growth_y2 -> 0.3 | F26: =revenue_growth_y3 -> 0.22 | G26: =revenue_growth_y4 -> 0.16 | H26: =revenue_growth_y5 -> 0.1
A28: Cost of goods sold
A30: COGS - Primary
A31: =A9 -> Core business baseline carryover | D31: =IFERROR((D25-D47)*D9/D25,0) -> 38000 | E31: =IFERROR((E25-E47)*E9/E25,0) -> 52200 | F31: =IFERROR((F25-F47)*F9/F25,0) -> 65975 | G31: =IFERROR((G25-G47)*G9/G25,0) -> 80489.5 | H31: =IFERROR((H25-H47)*H9/H25,0) -> 90700.168
A32: =A10 -> Capped baseline growth | D32: =IFERROR((D25-D47)*D10/D25,0) -> 17100 | E32: =IFERROR((E25-E47)*E10/E25,0) -> 15660 | F32: =IFERROR((F25-F47)*F10/F25,0) -> 14514.5 | G32: =IFERROR((G25-G47)*G10/G25,0) -> 12878.32 | H32: =IFERROR((H25-H47)*H10/H25,0) -> 9070.0168
A33: COGS - Others
A34: =A13 -> Core business excess upside | D34: =IFERROR((D25-D47)*D13/D25,0) -> -55100 | E34: =IFERROR((E25-E47)*E13/E25,0) -> -67860 | F34: =IFERROR((F25-F47)*F13/F25,0) -> -80489.5 | G34: =IFERROR((G25-G47)*G13/G25,0) -> -93367.82 | H34: =IFERROR((H25-H47)*H13/H25,0) -> -99770.185
A35: =A14 | D35: =IFERROR((D25-D47)*D14/D25,0) -> 0 | E35: =IFERROR((E25-E47)*E14/E25,0) -> 0 | F35: =IFERROR((F25-F47)*F14/F25,0) -> 0 | G35: =IFERROR((G25-G47)*G14/G25,0) -> 0 | H35: =IFERROR((H25-H47)*H14/H25,0) -> 0
A36: =A15 | D36: =IFERROR((D25-D47)*D15/D25,0) -> 0 | E36: =IFERROR((E25-E47)*E15/E25,0) -> 0 | F36: =IFERROR((F25-F47)*F15/F25,0) -> 0 | G36: =IFERROR((G25-G47)*G15/G25,0) -> 0 | H36: =IFERROR((H25-H47)*H15/H25,0) -> 0
A37: =A16 | D37: =IFERROR((D25-D47)*D16/D25,0) -> 0 | E37: =IFERROR((E25-E47)*E16/E25,0) -> 0 | F37: =IFERROR((F25-F47)*F16/F25,0) -> 0 | G37: =IFERROR((G25-G47)*G16/G25,0) -> 0 | H37: =IFERROR((H25-H47)*H16/H25,0) -> 0
A38: =A17 | D38: =IFERROR((D25-D47)*D17/D25,0) -> 0 | E38: =IFERROR((E25-E47)*E17/E25,0) -> 0 | F38: =IFERROR((F25-F47)*F17/F25,0) -> 0 | G38: =IFERROR((G25-G47)*G17/G25,0) -> 0 | H38: =IFERROR((H25-H47)*H17/H25,0) -> 0
A39: =A18 | D39: =IFERROR((D25-D47)*D18/D25,0) -> 0 | E39: =IFERROR((E25-E47)*E18/E25,0) -> 0 | F39: =IFERROR((F25-F47)*F18/F25,0) -> 0 | G39: =IFERROR((G25-G47)*G18/G25,0) -> 0 | H39: =IFERROR((H25-H47)*H18/H25,0) -> 0
A40: =A19 | D40: =IFERROR((D25-D47)*D19/D25,0) -> 0 | E40: =IFERROR((E25-E47)*E19/E25,0) -> 0 | F40: =IFERROR((F25-F47)*F19/F25,0) -> 0 | G40: =IFERROR((G25-G47)*G19/G25,0) -> 0 | H40: =IFERROR((H25-H47)*H19/H25,0) -> 0
A41: =A20 | D41: =IFERROR((D25-D47)*D20/D25,0) -> 0 | E41: =IFERROR((E25-E47)*E20/E25,0) -> 0 | F41: =IFERROR((F25-F47)*F20/F25,0) -> 0 | G41: =IFERROR((G25-G47)*G20/G25,0) -> 0 | H41: =IFERROR((H25-H47)*H20/H25,0) -> 0
A42: =A21 | D42: =IFERROR((D25-D47)*D21/D25,0) -> 0 | E42: =IFERROR((E25-E47)*E21/E25,0) -> 0 | F42: =IFERROR((F25-F47)*F21/F25,0) -> 0 | G42: =IFERROR((G25-G47)*G21/G25,0) -> 0 | H42: =IFERROR((H25-H47)*H21/H25,0) -> 0
A43: =A22 -> Unallocated model adjustment | D43: =IFERROR((D25-D47)*D22/D25,0) -> 55100 | E43: =IFERROR((E25-E47)*E22/E25,0) -> 67860 | F43: =IFERROR((F25-F47)*F22/F25,0) -> 80489.5 | G43: =IFERROR((G25-G47)*G22/G25,0) -> 93367.82 | H43: =IFERROR((H25-H47)*H22/H25,0) -> 99770.185
A44: Total COGS | B44: (currency × unit) | D44: =SUM(D31:D43) -> 55100 | E44: =SUM(E31:E43) -> 67860 | F44: =SUM(F31:F43) -> 80489.5 | G44: =SUM(G31:G43) -> 93367.82 | H44: =SUM(H31:H43) -> 99770.185
A46: Profitability
...

Sheet DCF
A1: DCF — Per Management scenario
A2: FCFF schedule from Projections, discounted at scenario WACC. Convention: full-period discounting (no stub-year partial); terminal value computed at end of Y5 and PV'd at the same Y5 discount factor.
A4: Item | B4: Unit | D4: Y1 | E4: Y2 | F4: Y3 | G4: Y4 | H4: Y5 | I4: Terminal
A6: Discount inputs
A7: WACC (this scenario) | B7: % | D7: =wacc_per_mgmt -> 0.13905529
A8: Terminal growth rate | B8: % | D8: =terminal_growth_rate -> 0.03
A10: FCFF & discount mechanics
A11: FCFF | B11: (currency × unit) | D11: =Projections!D71 -> -2889.5 | E11: =Projections!E71 -> 10280.5 | F11: =Projections!F71 -> 27222.416 | G11: =Projections!G71 -> 39125.256 | H11: =Projections!H71 -> 51448.336
A12: Discount period | B12: years | D12: 1 | E12: 2 | F12: 3 | G12: 4 | H12: 5
A13: Discount factor | B13: x | D13: =1/(1+wacc_per_mgmt)^D12 -> 0.87792051 | E13: =1/(1+wacc_per_mgmt)^E12 -> 0.77074441 | F13: =1/(1+wacc_per_mgmt)^F12 -> 0.67665232 | G13: =1/(1+wacc_per_mgmt)^G12 -> 0.59404695 | H13: =1/(1+wacc_per_mgmt)^H12 -> 0.521526
A14: PV of FCFF | B14: (currency × unit) | D14: =D11*D13 -> -2536.7513 | E14: =E11*E13 -> 7923.6379 | F14: =F11*F13 -> 18420.111 | G14: =G11*G13 -> 23242.239 | H14: =H11*H13 -> 26831.645
A16: Terminal value
A17: Method | I17: =terminal_method -> gordon_growth
A18: Y5 FCFF | B18: (currency × unit) | I18: =Projections!H71 -> 51448.336
A19: Terminal value — Gordon Growth | B19: (currency × unit) | I19: =IFERROR(I18*(1+terminal_growth_rate)/(wacc_per_mgmt-terminal_growth_rate),0) -> 485916.68
A20: Terminal value — Exit Multiple | B20: (currency × unit) | I20: =IF(EXACT(terminal_exit_multiple_type,"EV/EBITDA"),Projections!H50*terminal_exit_multiple_value,IF(EXACT(terminal_exit_multiple_type,"EV/Sales"),Projections!H25*terminal_exit_multiple_value,IF(EXACT(terminal_exit_multiple_type,"P/E"),Projections!H58*terminal_exit_multiple_value,0))) -> 0
A21: Selected terminal value | B21: (currency × unit) | I21: =IF(EXACT(terminal_method,"exit_multiple"),I20,I19) -> 485916.68
A22: PV of terminal value | B22: (currency × unit) | I22: =I21*H13 -> 253418.18
A24: Enterprise Value
A25: Sum of PV of explicit-period FCFF | I25: =SUM(D14:H14) -> 73880.882
A26: + PV of terminal value | I26: =I22 -> 253418.18
A27: Enterprise Value | I27: =I25+I26 -> 327299.06

Sheet DCF (Independent)
A1: DCF — Independent scenario
A2: FCFF schedule from Projections, discounted at scenario WACC. Convention: full-period discounting (no stub-year partial); terminal value computed at end of Y5 and PV'd at the same Y5 discount factor.
A4: Item | B4: Unit | D4: Y1 | E4: Y2 | F4: Y3 | G4: Y4 | H4: Y5 | I4: Terminal
A6: Discount inputs
A7: WACC (this scenario) | B7: % | D7: =wacc_indep -> 0.1558895
A8: Terminal growth rate | B8: % | D8: =terminal_growth_rate -> 0.03
A10: FCFF & discount mechanics
A11: FCFF | B11: (currency × unit) | D11: =Projections!D71 -> -2889.5 | E11: =Projections!E71 -> 10280.5 | F11: =Projections!F71 -> 27222.416 | G11: =Projections!G71 -> 39125.256 | H11: =Projections!H71 -> 51448.336
A12: Discount period | B12: years | D12: 1 | E12: 2 | F12: 3 | G12: 4 | H12: 5
A13: Discount factor | B13: x | D13: =1/(1+wacc_indep)^D12 -> 0.8651346 | E13: =1/(1+wacc_indep)^E12 -> 0.74845788 | F13: =1/(1+wacc_indep)^F12 -> 0.6475168 | G13: =1/(1+wacc_indep)^G12 -> 0.56018919 | H13: =1/(1+wacc_indep)^H12 -> 0.48463905
A14: PV of FCFF | B14: (currency × unit) | D14: =D11*D13 -> -2499.8064 | E14: =E11*E13 -> 7694.5212 | F14: =F11*F13 -> 17626.972 | G14: =G11*G13 -> 21917.546 | H14: =H11*H13 -> 24933.873
A16: Terminal value
A17: Method | I17: =terminal_method -> gordon_growth
A18: Y5 FCFF | B18: (currency × unit) | I18: =Projections!H71 -> 51448.336
A19: Terminal value — Gordon Growth | B19: (currency × unit) | I19: =IFERROR(I18*(1+terminal_growth_rate)/(wacc_indep-terminal_growth_rate),0) -> 420938.89
A20: Terminal value — Exit Multiple | B20: (currency × unit) | I20: =IF(EXACT(terminal_exit_multiple_type,"EV/EBITDA"),Projections!H50*terminal_exit_multiple_value,IF(EXACT(terminal_exit_multiple_type,"EV/Sales"),Projections!H25*terminal_exit_multiple_value,IF(EXACT(terminal_exit_multiple_type,"P/E"),Projections!H58*terminal_exit_multiple_value,0))) -> 0
A21: Selected terminal value | B21: (currency × unit) | I21: =IF(EXACT(terminal_method,"exit_multiple"),I20,I19) -> 420938.89
A22: PV of terminal value | B22: (currency × unit) | I22: =I21*H13 -> 204003.43
A24: Enterprise Value
A25: Sum of PV of explicit-period FCFF | I25: =SUM(D14:H14) -> 69673.105
A26: + PV of terminal value | I26: =I22 -> 204003.43
A27: Enterprise Value | I27: =I25+I26 -> 273676.53

Sheet Comps
A1: Comps — comparable companies cross-check
A2: Apply CoCo NTM trading multiples to target Y1 metrics. Implied EV from EV/Sales × Revenue and EV/EBITDA × EBITDA cross-check the DCF. P/E × Net Income gives implied Equity (bridge to EV via surplus/net debt).
A4: Multiple | B4: Target metric (Y1) | C4: CoCo Q1 | D4: CoCo Median | E4: CoCo Q3 | F4: Implied (low) | G4: Implied (mid) | H4: Implied (high)
A6: NTM-based multiples (applied to Y1)
A7: EV/Sales NTM | B7: =Projections!D25 -> 145000 | C7: ='CoCo Multiples'!F41 -> 3.075 | D7: ='CoCo Multiples'!F39 -> 3.35 | E7: ='CoCo Multiples'!F38 -> 3.775 | F7: =IFERROR(B7*C7,"n/a") -> 445875 | G7: =IFERROR(B7*D7,"n/a") -> 485750 | H7: =IFERROR(B7*E7,"n/a") -> 547375
A8: EV/EBITDA NTM | B8: =Projections!D50 -> 10150 | C8: ='CoCo Multiples'!H41 -> 13.125 | D8: ='CoCo Multiples'!H39 -> 14.25 | E8: ='CoCo Multiples'!H38 -> 15.75 | F8: =IFERROR(B8*C8,"n/a") -> 133218.75 | G8: =IFERROR(B8*D8,"n/a") -> 144637.5 | H8: =IFERROR(B8*E8,"n/a") -> 159862.5
A9: P/E NTM (gives Equity) | B9: =Projections!D58 -> 3610.5 | C9: ='CoCo Multiples'!J41 -> 19.5 | D9: ='CoCo Multiples'!J39 -> 21 | E9: ='CoCo Multiples'!J38 -> 23 | F9: =IFERROR(B9*C9,"n/a") -> 70404.75 | G9: =IFERROR(B9*D9,"n/a") -> 75820.5 | H9: =IFERROR(B9*E9,"n/a") -> 83041.5
A11: LTM-based multiples (not wired in v1 — needs Historical FS link)
A12: TODO: when Historical FS sheet is built, wire LTM target metrics here and apply 'CoCo Multiples'!E/G/I (LTM) columns.
A14: Cross-check summary — DCF vs CoCo-implied
A15: DCF EV — Per Management | B15: =DCF!I27 -> 327299.06
A16: DCF EV — Independent | B16: ='DCF (Independent)'!I27 -> 273676.53
A17: CoCo-implied EV — EV/Sales NTM (Median) | B17: =G7 -> 485750
A18: CoCo-implied EV — EV/EBITDA NTM (Median) | B18: =G8 -> 144637.5
A19: CoCo-implied Equity — P/E NTM (Median) | B19: =G9 -> 75820.5
A20: CoCo-implied EV — P/E NTM (bridged from Equity) | B20: =G9-surplus_assets-non_operating_assets+IF(ISNUMBER(net_debt_override),net_debt_override,0)+minority_interests -> 50820.5
A21: Mean of CoCo-implied EVs (Sales + EBITDA + P/E) | B21: =AVERAGE(B17,B18,B20) -> 227069.33

Sheet Football Field
A1: Football Field — methodology ranges (DCF primary; others cross-checks)
A2: Range chart input. DCF range comes from the two WACC scenarios and is the primary methodology (weight_dcf = 1.0). Comps range from CoCo Q1/Median/Q3 and Precedent range from precedents_table are retained as cross-checks against the DCF EV (±10% band, see rows 22-26).
A4: Methodology | B4: Low | C4: Mid | D4: High | E4: Weight | F4: Weighted Mid | G4: Notes
A6: Methodology ranges (EV in currency × unit)
A7: DCF (across scenarios) | B7: =MIN(DCF!I27,'DCF (Independent)'!I27) -> 273676.53 | C7: =AVERAGE(DCF!I27,'DCF (Independent)'!I27) -> 300487.8 | D7: =MAX(DCF!I27,'DCF (Independent)'!I27) -> 327299.06 | E7: =weight_dcf -> 0.5 | F7: =C7*E7 -> 150243.9 | G7: Low = Per-Mgmt vs Indep min; High = max; Mid = average
A8: Comps — EV/Sales NTM | B8: =Comps!F7 -> 445875 | C8: =Comps!G7 -> 485750 | D8: =Comps!H7 -> 547375 | G8: Reference; weighted via combined Comps row below
A9: Comps — EV/EBITDA NTM | B9: =Comps!F8 -> 133218.75 | C9: =Comps!G8 -> 144637.5 | D9: =Comps!H8 -> 159862.5 | G9: Reference
A10: Comps — P/E NTM (EV after bridge) | B10: =Comps!F9-surplus_assets-non_operating_assets+IF(ISNUMBER(net_debt_override),net_debt_override,0)+minority_interests -> 45404.75 | C10: =Comps!G9-surplus_assets-non_operating_assets+IF(ISNUMBER(net_debt_override),net_debt_override,0)+minority_interests -> 50820.5 | D10: =Comps!H9-surplus_assets-non_operating_assets+IF(ISNUMBER(net_debt_override),net_debt_override,0)+minority_interests -> 58041.5 | G10: Reference; bridged from Equity
A11: Comps — combined (mean of 3 methodologies) | B11: =MIN(C8,C9,C10) -> 50820.5 | C11: =AVERAGE(C8,C9,C10) -> 227069.33 | D11: =MAX(C8,C9,C10) -> 485750 | E11: =weight_comps -> 0.3 | F11: =C11*E11 -> 68120.8 | G11: Low/High across the 3 mids; Mid is mean
A12: Precedent transactions | B12: =IFERROR(MIN(IF(INDEX(precedents_table,0,1)=TRUE(),INDEX(precedents_table,0,7)*Projections!D50,"")),0) -> 0 | C12: =IFERROR(AVERAGEIFS(INDEX(precedents_table,0,7),INDEX(precedents_table,0,1),TRUE())*Projections!D50,0) -> 243600 | D12: =IFERROR(MAX(IF(INDEX(precedents_table,0,1)=TRUE(),INDEX(precedents_table,0,7)*Projections!D50,"")),0) -> 0 | E12: =weight_precedent -> 0.2 | F12: =C12*E12 -> 48720 | G12: Mean EV/EBITDA × Y1 EBITDA across included precedents
A14: Concluded valuation (DCF primary)
A15: Total weight applied | E15: =E7+E11+E12 -> 1
A16: Concluded EV (DCF primary) | F16: =IFERROR((F7+F11+F12)/E15,0) -> 267084.7
A17: Selected valuation (manual override)
A18: Selected low | B18: =selected_low -> 0
A19: Selected mid | C19: =selected_mid -> 0
A20: Selected high | D20: =selected_high -> 0
A22: Cross-checks vs DCF enterprise value (±10% band)
A23: Cross-check | B23: Implied EV | C23: Variance vs DCF | D23: Assessment
A24: Market approach (Comps combined) | B24: =C11 -> 227069.33 | C24: =IF(OR(C11=0,DCF!I27=0),"n/a",C11/DCF!I27-1) -> -0.30623286 | D24: =IF(OR(C11=0,DCF!I27=0),"Not available",IF(ABS(C11/DCF!I27-1)<=0.1,"Within reasonable range","Outside cross-check range")) -> Outside cross-check range
A25: Precedent transactions | B25: =C12 -> 243600 | C25: =IF(OR(C12=0,DCF!I27=0),"n/a",C12/DCF!I27-1) -> -0.25572656 | D25: =IF(OR(C12=0,DCF!I27=0),"Not available",IF(ABS(C12/DCF!I27-1)<=0.1,"Within reasonable range","Outside cross-check range")) -> Outside cross-check range
A26: Overall cross-check verdict | D26: =IF(AND(D24="Not available",D25="Not available"),"Not available",IF(OR(D24="Outside cross-check range",D25="Outside cross-check range"),"Outside cross-check range","Within reasonable range")) -> Outside cross-check range

Sheet WACC
A1: WACC — discount rate build-up
A2: Two scenarios. Inputs (Rf, ERP, country premium) shared; beta / D/E / size / specific / Kd are scenario-specific. Calculated outputs (levered beta, Ke, after-tax Kd, WACC) cycle back to the Inputs sheet.
A4: Component | C4: Type | E4: Per Management | F4: Independent
A6: Cost of Equity (Ke)
A7: Effective tax rate | C7: % | E7: =IF(ISNUMBER(tax_effective_rate),tax_effective_rate,tax_rate_high) -> 0.17 | F7: =IF(ISNUMBER(tax_effective_rate),tax_effective_rate,tax_rate_high) -> 0.17
A8: Unlevered beta | C8: x | E8: =unlevered_beta_per_mgmt -> 1.05 | F8: =unlevered_beta_indep -> 1.15
A9: D/E ratio | C9: % | E9: =target_debt_to_equity_per_mgmt -> 0.2 | F9: =target_debt_to_equity_indep -> 0.25
A10: Levered beta (calc) | C10: x | E10: =E8*(1+(1-E7)*E9) -> 1.2243 | F10: =F8*(1+(1-F7)*F9) -> 1.388625
A11: Risk-free rate | C11: % | E11: =risk_free_rate -> 0.045 | F11: =risk_free_rate -> 0.045
A12: Equity risk premium (ERP) | C12: % | E12: =equity_risk_premium -> 0.055 | F12: =equity_risk_premium -> 0.055
A13: Country risk premium | C13: % | E13: =country_risk_premium -> 0.005 | F13: =country_risk_premium -> 0.005
A14: Size premium | C14: % | E14: =size_premium_per_mgmt -> 0.02 | F14: =size_premium_indep -> 0.025
A15: Specific risk premium | C15: % | E15: =specific_risk_premium_per_mgmt -> 0.02 | F15: =specific_risk_premium_indep -> 0.03
A16: Cost of Equity (calc) | C16: % | E16: =E11+E10*E12+E13+E14+E15 -> 0.1573365 | F16: =F11+F10*F12+F13+F14+F15 -> 0.18137438
A18: Cost of Debt (Kd)
A19: Pre-tax cost of debt | C19: % | E19: =pretax_cost_of_debt_per_mgmt -> 0.06 | F19: =pretax_cost_of_debt_indep -> 0.065
A20: After-tax cost of debt (calc) | C20: % | E20: =E19*(1-E7) -> 0.0498 | F20: =F19*(1-F7) -> 0.05395
A22: Capital structure & WACC
A23: D/V (debt weight) | C23: % | E23: =target_debt_weight_per_mgmt -> 0.17 | F23: =target_debt_weight_indep -> 0.2
A24: E/V (equity weight) | C24: % | E24: =target_equity_weight_per_mgmt -> 0.83 | F24: =target_equity_weight_indep -> 0.8
A25: WACC (calc) | C25: % | E25: =E16*E24+E20*E23 -> 0.13905529 | F25: =F16*F24+F20*F23 -> 0.1558895

Sheet CoCo Selection
A1: CoCo Selection — comparable companies
A2: Mirror view of the comparable companies table on the Inputs sheet. Edit values on Inputs; this sheet refreshes automatically.
A4: Tier | B4: Include | C4: Company | D4: Ticker | E4: Business description | F4: Country | G4: Accounting standard | H4: Market cap (USD mm) | I4: D/E ratio | J4: Raw levered beta | K4: Effective tax rate | L4: Unlevered beta (calculated)
A6: =Inputs!A127 -> selected_mid | B6: =Inputs!B127 -> Selected valuation mid | C6: =Inputs!C127 -> currency | D6: =Inputs!D127 -> 0 | E6: =Inputs!E127 -> 0 | F6: =Inputs!F127 -> 0 | G6: =Inputs!G127 -> 0 | H6: =Inputs!H127 -> 0 | ... K6: =Inputs!K127 -> 0 | L6: =IFERROR(Inputs!J127/(1+(1-Inputs!K127)*Inputs!I127),"") -> 0
A7: =Inputs!A128 -> selected_high | B7: =Inputs!B128 -> Selected valuation high | C7: =Inputs!C128 -> currency | D7: =Inputs!D128 -> 0 | E7: =Inputs!E128 -> 0 | F7: =Inputs!F128 -> 0 | G7: =Inputs!G128 -> 0 | H7: =Inputs!H128 -> 0 | ... K7: =Inputs!K128 -> 0 | L7: =IFERROR(Inputs!J128/(1+(1-Inputs!K128)*Inputs!I128),"") -> 0
A8: =Inputs!A129 -> 0 | B8: =Inputs!B129 -> 0 | C8: =Inputs!C129 -> 0 | D8: =Inputs!D129 -> 0 | E8: =Inputs!E129 -> 0 | F8: =Inputs!F129 -> 0 | G8: =Inputs!G129 -> 0 | H8: =Inputs!H129 -> 0 | ... K8: =Inputs!K129 -> 0 | L8: =IFERROR(Inputs!J129/(1+(1-Inputs!K129)*Inputs!I129),"") -> 0
A9: =Inputs!A130 -> Section L — Sensitivity ranges (Extended) | B9: =Inputs!B130 -> 0 | C9: =Inputs!C130 -> 0 | D9: =Inputs!D130 -> 0 | E9: =Inputs!E130 -> 0 | F9: =Inputs!F130 -> 0 | G9: =Inputs!G130 -> 0 | H9: =Inputs!H130 -> 0 | ... K9: =Inputs!K130 -> 0 | L9: =IFERROR(Inputs!J130/(1+(1-Inputs!K130)*Inputs!I130),"") -> 0
A10: =Inputs!A131 -> sens_wacc_step | B10: =Inputs!B131 -> WACC sensitivity step | C10: =Inputs!C131 -> percentage | D10: =Inputs!D131 -> 0.005 | E10: =Inputs!E131 -> 0 | F10: =Inputs!F131 -> 0 | G10: =Inputs!G131 -> 0 | H10: =Inputs!H131 -> 0 | ... K10: =Inputs!K131 -> 0 | L10: =IFERROR(Inputs!J131/(1+(1-Inputs!K131)*Inputs!I131),"") -> 0
A11: =Inputs!A132 -> sens_wacc_count | B11: =Inputs!B132 -> WACC steps each side of base | C11: =Inputs!C132 -> number | D11: =Inputs!D132 -> 5 | E11: =Inputs!E132 -> 0 | F11: =Inputs!F132 -> 0 | G11: =Inputs!G132 -> 0 | H11: =Inputs!H132 -> 0 | ... K11: =Inputs!K132 -> 0 | L11: =IFERROR(Inputs!J132/(1+(1-Inputs!K132)*Inputs!I132),"") -> 0
A12: =Inputs!A133 -> sens_terminal_g_step | B12: =Inputs!B133 -> Terminal g sensitivity step | C12: =Inputs!C133 -> percentage | D12: =Inputs!D133 -> 0.005 | E12: =Inputs!E133 -> 0 | F12: =Inputs!F133 -> 0 | G12: =Inputs!G133 -> 0 | H12: =Inputs!H133 -> 0 | ... K12: =Inputs!K133 -> 0 | L12: =IFERROR(Inputs!J133/(1+(1-Inputs!K133)*Inputs!I133),"") -> 0
A13: =Inputs!A134 -> sens_terminal_g_count | B13: =Inputs!B134 -> Terminal g steps each side | C13: =Inputs!C134 -> number | D13: =Inputs!D134 -> 5 | E13: =Inputs!E134 -> 0 | F13: =Inputs!F134 -> 0 | G13: =Inputs!G134 -> 0 | H13: =Inputs!H134 -> 0 | ... K13: =Inputs!K134 -> 0 | L13: =IFERROR(Inputs!J134/(1+(1-Inputs!K134)*Inputs!I134),"") -> 0
A14: =Inputs!A135 -> sens_revenue_g_step | B14: =Inputs!B135 -> Revenue growth sens step | C14: =Inputs!C135 -> percentage | D14: =Inputs!D135 -> 0.02 | E14: =Inputs!E135 -> 0 | F14: =Inputs!F135 -> 0 | G14: =Inputs!G135 -> 0 | H14: =Inputs!H135 -> 0 | ... K14: =Inputs!K135 -> 0 | L14: =IFERROR(Inputs!J135/(1+(1-Inputs!K135)*Inputs!I135),"") -> 0
A15: =Inputs!A136 -> sens_ebitda_margin_step | B15: =Inputs!B136 -> EBITDA margin sens step | C15: =Inputs!C136 -> percentage | D15: =Inputs!D136 -> 0.02 | E15: =Inputs!E136 -> 0 | F15: =Inputs!F136 -> 0 | G15: =Inputs!G136 -> 0 | H15: =Inputs!H136 -> 0 | ... K15: =Inputs!K136 -> 0 | L15: =IFERROR(Inputs!J136/(1+(1-Inputs!K136)*Inputs!I136),"") -> 0
A16: =Inputs!A137 -> 0 | B16: =Inputs!B137 -> 0 | C16: =Inputs!C137 -> 0 | D16: =Inputs!D137 -> 0 | E16: =Inputs!E137 -> 0 | F16: =Inputs!F137 -> 0 | G16: =Inputs!G137 -> 0 | H16: =Inputs!H137 -> 0 | ... K16: =Inputs!K137 -> 0 | L16: =IFERROR(Inputs!J137/(1+(1-Inputs!K137)*Inputs!I137),"") -> 0
A17: =Inputs!A138 -> Section G — Comparable companies table (Core) | B17: =Inputs!B138 -> 0 | C17: =Inputs!C138 -> 0 | D17: =Inputs!D138 -> 0 | E17: =Inputs!E138 -> 0 | F17: =Inputs!F138 -> 0 | G17: =Inputs!G138 -> 0 | H17: =Inputs!H138 -> 0 | ... K17: =Inputs!K138 -> 0 | L17: =IFERROR(Inputs!J138/(1+(1-Inputs!K138)*Inputs!I138),"") -> 0
... A35: =Inputs!A156 -> 0 | B35: =Inputs!B156 -> 0 | C35: =Inputs!C156 -> 0 | D35: =Inputs!D156 -> 0 | E35: =Inputs!E156 -> 0 | F35: =Inputs!F156 -> 0 | G35: =Inputs!G156 -> 0 | H35: =Inputs!H156 -> 0 | ... K35: =Inputs!K156 -> 0 | L35: =IFERROR(Inputs!J156/(1+(1-Inputs!K156)*Inputs!I156),"") -> 0

Sheet CoCo Multiples
A1: CoCo Multiples — trading multiples per comparable
A2: Per-CoCo metric values (Capital IQ / Bloomberg). Cols A-D mirror Inputs. Cols E onward are manual data entry. Summary stats compute below.
A4: Tier | B4: Include | C4: Company | D4: Ticker | E4: EV/Sales LTM | F4: EV/Sales NTM | G4: EV/EBITDA LTM | H4: EV/EBITDA NTM | I4: P/E LTM | J4: P/E NTM
A6: =Inputs!A127 -> selected_mid | B6: =Inputs!B127 -> Selected valuation mid | C6: =Inputs!C127 -> currency | D6: =Inputs!D127 -> 0 | E6: 4.2 | F6: 3.5 | G6: 18 | H6: 15 | I6: 26 | J6: 22
A7: =Inputs!A128 -> selected_high | B7: =Inputs!B128 -> Selected valuation high | C7: =Inputs!C128 -> currency | D7: =Inputs!D128 -> 0 | E7: 3.8 | F7: 3.2 | G7: 16.5 | H7: 13.5 | I7: 24 | J7: 20
A8: =Inputs!A129 -> 0 | B8: =Inputs!B129 -> 0 | C8: =Inputs!C129 -> 0 | D8: =Inputs!D129 -> 0 | E8: 5.5 | F8: 4.6 | G8: 22 | H8: 18 | I8: 32 | J8: 26
A9: =Inputs!A130 -> Section L — Sensitivity ranges (Extended) | B9: =Inputs!B130 -> 0 | C9: =Inputs!C130 -> 0 | D9: =Inputs!D130 -> 0 | E9: 3.1 | F9: 2.7 | G9: 14 | H9: 12 | I9: 21 | J9: 18
A10: =Inputs!A131 -> sens_wacc_step | B10: =Inputs!B131 -> WACC sensitivity step | C10: =Inputs!C131 -> percentage | D10: =Inputs!D131 -> 0.005
A11: =Inputs!A132 -> sens_wacc_count | B11: =Inputs!B132 -> WACC steps each side of base | C11: =Inputs!C132 -> number | D11: =Inputs!D132 -> 5
A12: =Inputs!A133 -> sens_terminal_g_step | B12: =Inputs!B133 -> Terminal g sensitivity step | C12: =Inputs!C133 -> percentage | D12: =Inputs!D133 -> 0.005
A13: =Inputs!A134 -> sens_terminal_g_count | B13: =Inputs!B134 -> Terminal g steps each side | C13: =Inputs!C134 -> number | D13: =Inputs!D134 -> 5
A14: =Inputs!A135 -> sens_revenue_g_step | B14: =Inputs!B135 -> Revenue growth sens step | C14: =Inputs!C135 -> percentage | D14: =Inputs!D135 -> 0.02
A15: =Inputs!A136 -> sens_ebitda_margin_step | B15: =Inputs!B136 -> EBITDA margin sens step | C15: =Inputs!C136 -> percentage | D15: =Inputs!D136 -> 0.02
A16: =Inputs!A137 -> 0 | B16: =Inputs!B137 -> 0 | C16: =Inputs!C137 -> 0 | D16: =Inputs!D137 -> 0
A17: =Inputs!A138 -> Section G — Comparable companies table (Core) | B17: =Inputs!B138 -> 0 | C17: =Inputs!C138 -> 0 | D17: =Inputs!D138 -> 0
A18: =Inputs!A139 -> Tier | B18: =Inputs!B139 -> Include | C18: =Inputs!C139 -> Company | D18: =Inputs!D139 -> Ticker
A19: =Inputs!A140 -> 1 | B19: =Inputs!B140 -> TRUE | C19: =Inputs!C140 -> Atlassian | D19: =Inputs!D140 -> NASDAQ:TEAM
A20: =Inputs!A141 -> 1 | B20: =Inputs!B141 -> TRUE | C20: =Inputs!C141 -> Datadog | D20: =Inputs!D141 -> NASDAQ:DDOG
A21: =Inputs!A142 -> 2 | B21: =Inputs!B142 -> TRUE | C21: =Inputs!C142 -> MongoDB | D21: =Inputs!D142 -> NASDAQ:MDB
... A35: =Inputs!A156 -> 0 | B35: =Inputs!B156 -> 0 | C35: =Inputs!C156 -> 0 | D35: =Inputs!D156 -> 0
D37: Maximum | E37: =IFERROR(MAX(E6:E35),"n/a") -> 5.5 | F37: =IFERROR(MAX(F6:F35),"n/a") -> 4.6 | G37: =IFERROR(MAX(G6:G35),"n/a") -> 22 | H37: =IFERROR(MAX(H6:H35),"n/a") -> 18 | I37: =IFERROR(MAX(I6:I35),"n/a") -> 32 | J37: =IFERROR(MAX(J6:J35),"n/a") -> 26
D38: Q3 (75%) | E38: =IFERROR(QUARTILE(E6:E35,3),"n/a") -> 4.525 | F38: =IFERROR(QUARTILE(F6:F35,3),"n/a") -> 3.775 | G38: =IFERROR(QUARTILE(G6:G35,3),"n/a") -> 19 | H38: =IFERROR(QUARTILE(H6:H35,3),"n/a") -> 15.75 | I38: =IFERROR(QUARTILE(I6:I35,3),"n/a") -> 27.5 | J38: =IFERROR(QUARTILE(J6:J35,3),"n/a") -> 23
D39: Median | E39: =IFERROR(MEDIAN(E6:E35),"n/a") -> 4 | F39: =IFERROR(MEDIAN(F6:F35),"n/a") -> 3.35 | G39: =IFERROR(MEDIAN(G6:G35),"n/a") -> 17.25 | H39: =IFERROR(MEDIAN(H6:H35),"n/a") -> 14.25 | I39: =IFERROR(MEDIAN(I6:I35),"n/a") -> 25 | J39: =IFERROR(MEDIAN(J6:J35),"n/a") -> 21
D40: Mean | E40: =IFERROR(AVERAGE(E6:E35),"n/a") -> 4.15 | F40: =IFERROR(AVERAGE(F6:F35),"n/a") -> 3.5 | G40: =IFERROR(AVERAGE(G6:G35),"n/a") -> 17.625 | H40: =IFERROR(AVERAGE(H6:H35),"n/a") -> 14.625 | I40: =IFERROR(AVERAGE(I6:I35),"n/a") -> 25.75 | J40: =IFERROR(AVERAGE(J6:J35),"n/a") -> 21.5
D41: Q1 (25%) | E41: =IFERROR(QUARTILE(E6:E35,1),"n/a") -> 3.625 | F41: =IFERROR(QUARTILE(F6:F35,1),"n/a") -> 3.075 | G41: =IFERROR(QUARTILE(G6:G35,1),"n/a") -> 15.875 | H41: =IFERROR(QUARTILE(H6:H35,1),"n/a") -> 13.125 | I41: =IFERROR(QUARTILE(I6:I35,1),"n/a") -> 23.25 | J41: =IFERROR(QUARTILE(J6:J35,1),"n/a") -> 19.5
D42: Minimum | E42: =IFERROR(MIN(E6:E35),"n/a") -> 3.1 | F42: =IFERROR(MIN(F6:F35),"n/a") -> 2.7 | G42: =IFERROR(MIN(G6:G35),"n/a") -> 14 | H42: =IFERROR(MIN(H6:H35),"n/a") -> 12 | I42: =IFERROR(MIN(I6:I35),"n/a") -> 21 | J42: =IFERROR(MIN(J6:J35),"n/a") -> 18
D44: Tier-filtered (include=TRUE)
D45: Tier 1 mean | E45: =IFERROR(AVERAGEIFS(E6:E35,$A$6:$A$35,1,$B$6:$B$35,TRUE()),"n/a") -> n/a | F45: =IFERROR(AVERAGEIFS(F6:F35,$A$6:$A$35,1,$B$6:$B$35,TRUE()),"n/a") -> n/a | G45: =IFERROR(AVERAGEIFS(G6:G35,$A$6:$A$35,1,$B$6:$B$35,TRUE()),"n/a") -> n/a | H45: =IFERROR(AVERAGEIFS(H6:H35,$A$6:$A$35,1,$B$6:$B$35,TRUE()),"n/a") -> n/a | I45: =IFERROR(AVERAGEIFS(I6:I35,$A$6:$A$35,1,$B$6:$B$35,TRUE()),"n/a") -> n/a | J45: =IFERROR(AVERAGEIFS(J6:J35,$A$6:$A$35,1,$B$6:$B$35,TRUE()),"n/a") -> n/a
D46: Tier 2 mean | E46: =IFERROR(AVERAGEIFS(E6:E35,$A$6:$A$35,2,$B$6:$B$35,TRUE()),"n/a") -> n/a | F46: =IFERROR(AVERAGEIFS(F6:F35,$A$6:$A$35,2,$B$6:$B$35,TRUE()),"n/a") -> n/a | G46: =IFERROR(AVERAGEIFS(G6:G35,$A$6:$A$35,2,$B$6:$B$35,TRUE()),"n/a") -> n/a | H46: =IFERROR(AVERAGEIFS(H6:H35,$A$6:$A$35,2,$B$6:$B$35,TRUE()),"n/a") -> n/a | I46: =IFERROR(AVERAGEIFS(I6:I35,$A$6:$A$35,2,$B$6:$B$35,TRUE()),"n/a") -> n/a | J46: =IFERROR(AVERAGEIFS(J6:J35,$A$6:$A$35,2,$B$6:$B$35,TRUE()),"n/a") -> n/a
D47: Tier 3 mean | E47: =IFERROR(AVERAGEIFS(E6:E35,$A$6:$A$35,3,$B$6:$B$35,TRUE()),"n/a") -> n/a | F47: =IFERROR(AVERAGEIFS(F6:F35,$A$6:$A$35,3,$B$6:$B$35,TRUE()),"n/a") -> n/a | G47: =IFERROR(AVERAGEIFS(G6:G35,$A$6:$A$35,3,$B$6:$B$35,TRUE()),"n/a") -> n/a | H47: =IFERROR(AVERAGEIFS(H6:H35,$A$6:$A$35,3,$B$6:$B$35,TRUE()),"n/a") -> n/a | I47: =IFERROR(AVERAGEIFS(I6:I35,$A$6:$A$35,3,$B$6:$B$35,TRUE()),"n/a") -> n/a | J47: =IFERROR(AVERAGEIFS(J6:J35,$A$6:$A$35,3,$B$6:$B$35,TRUE()),"n/a") -> n/a

Sheet CoCo Margins
A1: CoCo Margins — profitability per comparable
A2: Per-CoCo metric values (Capital IQ / Bloomberg). Cols A-D mirror Inputs. Cols E onward are manual data entry. Summary stats compute below.
A4: Tier | B4: Include | C4: Company | D4: Ticker | E4: Gross margin | F4: EBIT margin | G4: Net margin
A6: =Inputs!A127 -> selected_mid | B6: =Inputs!B127 -> Selected valuation mid | C6: =Inputs!C127 -> currency | D6: =Inputs!D127 -> 0 | E6: 0.55 | F6: 0.18 | G6: 0.12
A7: =Inputs!A128 -> selected_high | B7: =Inputs!B128 -> Selected valuation high | C7: =Inputs!C128 -> currency | D7: =Inputs!D128 -> 0 | E7: 0.52 | F7: 0.16 | G7: 0.1
A8: =Inputs!A129 -> 0 | B8: =Inputs!B129 -> 0 | C8: =Inputs!C129 -> 0 | D8: =Inputs!D129 -> 0 | E8: 0.62 | F8: 0.22 | G8: 0.16
A9: =Inputs!A130 -> Section L — Sensitivity ranges (Extended) | B9: =Inputs!B130 -> 0 | C9: =Inputs!C130 -> 0 | D9: =Inputs!D130 -> 0 | E9: 0.48 | F9: 0.14 | G9: 0.09
A10: =Inputs!A131 -> sens_wacc_step | B10: =Inputs!B131 -> WACC sensitivity step | C10: =Inputs!C131 -> percentage | D10: =Inputs!D131 -> 0.005
A11: =Inputs!A132 -> sens_wacc_count | B11: =Inputs!B132 -> WACC steps each side of base | C11: =Inputs!C132 -> number | D11: =Inputs!D132 -> 5
A12: =Inputs!A133 -> sens_terminal_g_step | B12: =Inputs!B133 -> Terminal g sensitivity step | C12: =Inputs!C133 -> percentage | D12: =Inputs!D133 -> 0.005
A13: =Inputs!A134 -> sens_terminal_g_count | B13: =Inputs!B134 -> Terminal g steps each side | C13: =Inputs!C134 -> number | D13: =Inputs!D134 -> 5
A14: =Inputs!A135 -> sens_revenue_g_step | B14: =Inputs!B135 -> Revenue growth sens step | C14: =Inputs!C135 -> percentage | D14: =Inputs!D135 -> 0.02
A15: =Inputs!A136 -> sens_ebitda_margin_step | B15: =Inputs!B136 -> EBITDA margin sens step | C15: =Inputs!C136 -> percentage | D15: =Inputs!D136 -> 0.02
A16: =Inputs!A137 -> 0 | B16: =Inputs!B137 -> 0 | C16: =Inputs!C137 -> 0 | D16: =Inputs!D137 -> 0
A17: =Inputs!A138 -> Section G — Comparable companies table (Core) | B17: =Inputs!B138 -> 0 | C17: =Inputs!C138 -> 0 | D17: =Inputs!D138 -> 0
A18: =Inputs!A139 -> Tier | B18: =Inputs!B139 -> Include | C18: =Inputs!C139 -> Company | D18: =Inputs!D139 -> Ticker
A19: =Inputs!A140 -> 1 | B19: =Inputs!B140 -> TRUE | C19: =Inputs!C140 -> Atlassian | D19: =Inputs!D140 -> NASDAQ:TEAM
A20: =Inputs!A141 -> 1 | B20: =Inputs!B141 -> TRUE | C20: =Inputs!C141 -> Datadog | D20: =Inputs!D141 -> NASDAQ:DDOG
A21: =Inputs!A142 -> 2 | B21: =Inputs!B142 -> TRUE | C21: =Inputs!C142 -> MongoDB | D21: =Inputs!D142 -> NASDAQ:MDB
... A35: =Inputs!A156 -> 0 | B35: =Inputs!B156 -> 0 | C35: =Inputs!C156 -> 0 | D35: =Inputs!D156 -> 0
D37: Maximum | E37: =IFERROR(MAX(E6:E35),"n/a") -> 0.62 | F37: =IFERROR(MAX(F6:F35),"n/a") -> 0.22 | G37: =IFERROR(MAX(G6:G35),"n/a") -> 0.16
D38: Q3 (75%) | E38: =IFERROR(QUARTILE(E6:E35,3),"n/a") -> 0.5675 | F38: =IFERROR(QUARTILE(F6:F35,3),"n/a") -> 0.19 | G38: =IFERROR(QUARTILE(G6:G35,3),"n/a") -> 0.13
D39: Median | E39: =IFERROR(MEDIAN(E6:E35),"n/a") -> 0.535 | F39: =IFERROR(MEDIAN(F6:F35),"n/a") -> 0.17 | G39: =IFERROR(MEDIAN(G6:G35),"n/a") -> 0.11
D40: Mean | E40: =IFERROR(AVERAGE(E6:E35),"n/a") -> 0.5425 | F40: =IFERROR(AVERAGE(F6:F35),"n/a") -> 0.175 | G40: =IFERROR(AVERAGE(G6:G35),"n/a") -> 0.1175
D41: Q1 (25%) | E41: =IFERROR(QUARTILE(E6:E35,1),"n/a") -> 0.51 | F41: =IFERROR(QUARTILE(F6:F35,1),"n/a") -> 0.155 | G41: =IFERROR(QUARTILE(G6:G35,1),"n/a") -> 0.0975
D42: Minimum | E42: =IFERROR(MIN(E6:E35),"n/a") -> 0.48 | F42: =IFERROR(MIN(F6:F35),"n/a") -> 0.14 | G42: =IFERROR(MIN(G6:G35),"n/a") -> 0.09
D44: Tier-filtered (include=TRUE)
D45: Tier 1 mean | E45: =IFERROR(AVERAGEIFS(E6:E35,$A$6:$A$35,1,$B$6:$B$35,TRUE()),"n/a") -> n/a | F45: =IFERROR(AVERAGEIFS(F6:F35,$A$6:$A$35,1,$B$6:$B$35,TRUE()),"n/a") -> n/a | G45: =IFERROR(AVERAGEIFS(G6:G35,$A$6:$A$35,1,$B$6:$B$35,TRUE()),"n/a") -> n/a
D46: Tier 2 mean | E46: =IFERROR(AVERAGEIFS(E6:E35,$A$6:$A$35,2,$B$6:$B$35,TRUE()),"n/a") -> n/a | F46: =IFERROR(AVERAGEIFS(F6:F35,$A$6:$A$35,2,$B$6:$B$35,TRUE()),"n/a") -> n/a | G46: =IFERROR(AVERAGEIFS(G6:G35,$A$6:$A$35,2,$B$6:$B$35,TRUE()),"n/a") -> n/a
D47: Tier 3 mean | E47: =IFERROR(AVERAGEIFS(E6:E35,$A$6:$A$35,3,$B$6:$B$35,TRUE()),"n/a") -> n/a | F47: =IFERROR(AVERAGEIFS(F6:F35,$A$6:$A$35,3,$B$6:$B$35,TRUE()),"n/a") -> n/a | G47: =IFERROR(AVERAGEIFS(G6:G35,$A$6:$A$35,3,$B$6:$B$35,TRUE()),"n/a") -> n/a

Sheet CoCo Ratios
A1: CoCo Ratios — financial ratios per comparable
A2: Per-CoCo metric values (Capital IQ / Bloomberg). Cols A-D mirror Inputs. Cols E onward are manual data entry. Summary stats compute below.
A4: Tier | B4: Include | C4: Company | D4: Ticker | E4: ROE | F4: ROA | G4: D/E | H4: Current ratio
A6: =Inputs!A127 -> selected_mid | B6: =Inputs!B127 -> Selected valuation mid | C6: =Inputs!C127 -> currency | D6: =Inputs!D127 -> 0 | E6: 0.18 | F6: 0.08 | G6: 0.2 | H6: 2.1
A7: =Inputs!A128 -> selected_high | B7: =Inputs!B128 -> Selected valuation high | C7: =Inputs!C128 -> currency | D7: =Inputs!D128 -> 0 | E7: 0.16 | F7: 0.07 | G7: 0.25 | H7: 1.9
A8: =Inputs!A129 -> 0 | B8: =Inputs!B129 -> 0 | C8: =Inputs!C129 -> 0 | D8: =Inputs!D129 -> 0 | E8: 0.22 | F8: 0.1 | G8: 0.15 | H8: 2.5
A9: =Inputs!A130 -> Section L — Sensitivity ranges (Extended) | B9: =Inputs!B130 -> 0 | C9: =Inputs!C130 -> 0 | D9: =Inputs!D130 -> 0 | E9: 0.14 | F9: 0.06 | G9: 0.3 | H9: 1.7
A10: =Inputs!A131 -> sens_wacc_step | B10: =Inputs!B131 -> WACC sensitivity step | C10: =Inputs!C131 -> percentage | D10: =Inputs!D131 -> 0.005
A11: =Inputs!A132 -> sens_wacc_count | B11: =Inputs!B132 -> WACC steps each side of base | C11: =Inputs!C132 -> number | D11: =Inputs!D132 -> 5
